[2024-04-20T18:24:57.362+0000] {taskinstance.py:1159} INFO - Dependencies all met for dep_context=non-requeueable deps ti=<TaskInstance: season.load_step manual__2024-04-20T18:24:56.119023+00:00 [queued]>
[2024-04-20T18:24:57.366+0000] {taskinstance.py:1159} INFO - Dependencies all met for dep_context=requeueable deps ti=<TaskInstance: season.load_step manual__2024-04-20T18:24:56.119023+00:00 [queued]>
[2024-04-20T18:24:57.366+0000] {taskinstance.py:1361} INFO - Starting attempt 1 of 1
[2024-04-20T18:24:57.373+0000] {taskinstance.py:1382} INFO - Executing <Task(PythonOperator): load_step> on 2024-04-20 18:24:56.119023+00:00
[2024-04-20T18:24:57.379+0000] {standard_task_runner.py:57} INFO - Started process 133 to run task
[2024-04-20T18:24:57.381+0000] {standard_task_runner.py:84} INFO - Running: ['***', 'tasks', 'run', 'season', 'load_step', 'manual__2024-04-20T18:24:56.119023+00:00', '--job-id', '250', '--raw', '--subdir', 'DAGS_FOLDER/get_seasons.py', '--cfg-path', '/tmp/tmp76yzeso8']
[2024-04-20T18:24:57.383+0000] {standard_task_runner.py:85} INFO - Job 250: Subtask load_step
[2024-04-20T18:24:57.408+0000] {task_command.py:416} INFO - Running <TaskInstance: season.load_step manual__2024-04-20T18:24:56.119023+00:00 [running]> on host 5e73d3fc8834
[2024-04-20T18:24:57.588+0000] {taskinstance.py:1662} INFO - Exporting env vars: AIRFLOW_CTX_DAG_OWNER='***' AIRFLOW_CTX_DAG_ID='season' AIRFLOW_CTX_TASK_ID='load_step' AIRFLOW_CTX_EXECUTION_DATE='2024-04-20T18:24:56.119023+00:00' AIRFLOW_CTX_TRY_NUMBER='1' AIRFLOW_CTX_DAG_RUN_ID='manual__2024-04-20T18:24:56.119023+00:00'
[2024-04-20T18:24:57.598+0000] {base.py:73} INFO - Using connection ID '***' for task execution.
[2024-04-20T18:24:57.599+0000] {taskinstance.py:1937} ERROR - Task failed with exception
Traceback (most recent call last):
  File "/home/airflow/.local/lib/python3.10/site-packages/airflow/operators/python.py", line 192, in execute
    return_value = self.execute_callable()
  File "/home/airflow/.local/lib/python3.10/site-packages/airflow/operators/python.py", line 209, in execute_callable
    return self.python_callable(*self.op_args, **self.op_kwargs)
  File "/opt/airflow/plugins/steps/get_id_season.py", line 45, in load
    hook.insert_rows(
  File "/home/airflow/.local/lib/python3.10/site-packages/airflow/providers/common/sql/hooks/sql.py", line 510, in insert_rows
    with closing(self.get_conn()) as conn:
  File "/home/airflow/.local/lib/python3.10/site-packages/airflow/providers/postgres/hooks/postgres.py", line 158, in get_conn
    self.conn = psycopg2.connect(**conn_args)
  File "/home/airflow/.local/lib/python3.10/site-packages/psycopg2/__init__.py", line 122, in connect
    conn = _connect(dsn, connection_factory=connection_factory, **kwasync)
psycopg2.OperationalError: connection to server at "localhost" (::1), port 5432 failed: Connection refused
	Is the server running on that host and accepting TCP/IP connections?
connection to server at "localhost" (127.0.0.1), port 5432 failed: Connection refused
	Is the server running on that host and accepting TCP/IP connections?

[2024-04-20T18:24:57.603+0000] {taskinstance.py:1400} INFO - Marking task as FAILED. dag_id=season, task_id=load_step, execution_date=20240420T182456, start_date=20240420T182457, end_date=20240420T182457
[2024-04-20T18:24:57.608+0000] {standard_task_runner.py:104} ERROR - Failed to execute job 250 for task load_step (connection to server at "localhost" (::1), port 5432 failed: Connection refused
	Is the server running on that host and accepting TCP/IP connections?
connection to server at "localhost" (127.0.0.1), port 5432 failed: Connection refused
	Is the server running on that host and accepting TCP/IP connections?
; 133)
[2024-04-20T18:24:57.633+0000] {local_task_job_runner.py:228} INFO - Task exited with return code 1
[2024-04-20T18:24:57.645+0000] {taskinstance.py:2778} INFO - 0 downstream tasks scheduled from follow-on schedule check
