[2024-04-20T18:51:02.988+0000] {local_task_job_runner.py:120} INFO - ::group::Pre task execution logs
[2024-04-20T18:51:03.004+0000] {taskinstance.py:2073} INFO - Dependencies all met for dep_context=non-requeueable deps ti=<TaskInstance: season.load_step manual__2024-04-20T18:51:00.376851+00:00 [queued]>
[2024-04-20T18:51:03.008+0000] {taskinstance.py:2073} INFO - Dependencies all met for dep_context=requeueable deps ti=<TaskInstance: season.load_step manual__2024-04-20T18:51:00.376851+00:00 [queued]>
[2024-04-20T18:51:03.008+0000] {taskinstance.py:2303} INFO - Starting attempt 1 of 1
[2024-04-20T18:51:03.016+0000] {taskinstance.py:2327} INFO - Executing <Task(PythonOperator): load_step> on 2024-04-20 18:51:00.376851+00:00
[2024-04-20T18:51:03.023+0000] {warnings.py:110} WARNING - /home/***/.local/lib/python3.12/site-packages/***/task/task_runner/standard_task_runner.py:61: DeprecationWarning: This process (pid=59) is multi-threaded, use of fork() may lead to deadlocks in the child.
  pid = os.fork()

[2024-04-20T18:51:03.024+0000] {standard_task_runner.py:63} INFO - Started process 67 to run task
[2024-04-20T18:51:03.024+0000] {standard_task_runner.py:90} INFO - Running: ['***', 'tasks', 'run', 'season', 'load_step', 'manual__2024-04-20T18:51:00.376851+00:00', '--job-id', '7', '--raw', '--subdir', 'DAGS_FOLDER/get_seasons.py', '--cfg-path', '/tmp/tmpsoj6ykbi']
[2024-04-20T18:51:03.026+0000] {standard_task_runner.py:91} INFO - Job 7: Subtask load_step
[2024-04-20T18:51:03.053+0000] {task_command.py:426} INFO - Running <TaskInstance: season.load_step manual__2024-04-20T18:51:00.376851+00:00 [running]> on host 4cf9e140f22c
[2024-04-20T18:51:03.104+0000] {taskinstance.py:2644} INFO - Exporting env vars: AIRFLOW_CTX_DAG_OWNER='***' AIRFLOW_CTX_DAG_ID='season' AIRFLOW_CTX_TASK_ID='load_step' AIRFLOW_CTX_EXECUTION_DATE='2024-04-20T18:51:00.376851+00:00' AIRFLOW_CTX_TRY_NUMBER='1' AIRFLOW_CTX_DAG_RUN_ID='manual__2024-04-20T18:51:00.376851+00:00'
[2024-04-20T18:51:03.104+0000] {taskinstance.py:430} INFO - ::endgroup::
[2024-04-20T18:51:03.116+0000] {base.py:84} INFO - Using connection ID '***' for task execution.
[2024-04-20T18:51:03.117+0000] {taskinstance.py:441} INFO - ::group::Post task execution logs
[2024-04-20T18:51:03.117+0000] {taskinstance.py:2890} ERROR - Task failed with exception
Traceback (most recent call last):
  File "/home/airflow/.local/lib/python3.12/site-packages/airflow/models/taskinstance.py", line 465, in _execute_task
    result = _execute_callable(context=context, **execute_callable_kwargs)
             ^^^^^^^^^^^^^^^^^^^^^^^^^^^^^^^^^^^^^^^^^^^^^^^^^^^^^^^^^^^^^
  File "/home/airflow/.local/lib/python3.12/site-packages/airflow/models/taskinstance.py", line 432, in _execute_callable
    return execute_callable(context=context, **execute_callable_kwargs)
           ^^^^^^^^^^^^^^^^^^^^^^^^^^^^^^^^^^^^^^^^^^^^^^^^^^^^^^^^^^^^
  File "/home/airflow/.local/lib/python3.12/site-packages/airflow/models/baseoperator.py", line 400, in wrapper
    return func(self, *args, **kwargs)
           ^^^^^^^^^^^^^^^^^^^^^^^^^^^
  File "/home/airflow/.local/lib/python3.12/site-packages/airflow/operators/python.py", line 235, in execute
    return_value = self.execute_callable()
                   ^^^^^^^^^^^^^^^^^^^^^^^
  File "/home/airflow/.local/lib/python3.12/site-packages/airflow/operators/python.py", line 252, in execute_callable
    return self.python_callable(*self.op_args, **self.op_kwargs)
           ^^^^^^^^^^^^^^^^^^^^^^^^^^^^^^^^^^^^^^^^^^^^^^^^^^^^^
  File "/opt/airflow/plugins/steps/get_id_season.py", line 45, in load
    hook.insert_rows(
  File "/home/airflow/.local/lib/python3.12/site-packages/airflow/providers/common/sql/hooks/sql.py", line 544, in insert_rows
    with closing(self.get_conn()) as conn:
                 ^^^^^^^^^^^^^^^
  File "/home/airflow/.local/lib/python3.12/site-packages/airflow/providers/postgres/hooks/postgres.py", line 161, in get_conn
    self.conn = psycopg2.connect(**conn_args)
                ^^^^^^^^^^^^^^^^^^^^^^^^^^^^^
  File "/home/airflow/.local/lib/python3.12/site-packages/psycopg2/__init__.py", line 122, in connect
    conn = _connect(dsn, connection_factory=connection_factory, **kwasync)
           ^^^^^^^^^^^^^^^^^^^^^^^^^^^^^^^^^^^^^^^^^^^^^^^^^^^^^^^^^^^^^^^
psycopg2.OperationalError: connection to server at "127.0.0.1", port 5432 failed: Connection refused
	Is the server running on that host and accepting TCP/IP connections?

[2024-04-20T18:51:03.122+0000] {taskinstance.py:1205} INFO - Marking task as FAILED. dag_id=season, task_id=load_step, execution_date=20240420T185100, start_date=20240420T185103, end_date=20240420T185103
[2024-04-20T18:51:03.129+0000] {standard_task_runner.py:110} ERROR - Failed to execute job 7 for task load_step (connection to server at "127.0.0.1", port 5432 failed: Connection refused
	Is the server running on that host and accepting TCP/IP connections?
; 67)
[2024-04-20T18:51:03.157+0000] {local_task_job_runner.py:240} INFO - Task exited with return code 1
[2024-04-20T18:51:03.170+0000] {taskinstance.py:3482} INFO - 0 downstream tasks scheduled from follow-on schedule check
[2024-04-20T18:51:03.171+0000] {local_task_job_runner.py:222} INFO - ::endgroup::
