[2024-05-23T14:11:31.856+0000] {local_task_job_runner.py:120} INFO - ::group::Pre task execution logs
[2024-05-23T14:11:31.868+0000] {taskinstance.py:2073} INFO - Dependencies all met for dep_context=non-requeueable deps ti=<TaskInstance: games.load_data manual__2024-05-23T14:06:40.025463+00:00 [queued]>
[2024-05-23T14:11:31.873+0000] {taskinstance.py:2073} INFO - Dependencies all met for dep_context=requeueable deps ti=<TaskInstance: games.load_data manual__2024-05-23T14:06:40.025463+00:00 [queued]>
[2024-05-23T14:11:31.873+0000] {taskinstance.py:2303} INFO - Starting attempt 1 of 1
[2024-05-23T14:11:31.881+0000] {taskinstance.py:2327} INFO - Executing <Task(PythonOperator): load_data> on 2024-05-23 14:06:40.025463+00:00
[2024-05-23T14:11:31.888+0000] {warnings.py:110} WARNING - /home/***/.local/lib/python3.12/site-packages/***/task/task_runner/standard_task_runner.py:61: DeprecationWarning: This process (pid=170) is multi-threaded, use of fork() may lead to deadlocks in the child.
  pid = os.fork()

[2024-05-23T14:11:31.889+0000] {standard_task_runner.py:63} INFO - Started process 172 to run task
[2024-05-23T14:11:31.889+0000] {standard_task_runner.py:90} INFO - Running: ['***', 'tasks', 'run', 'games', 'load_data', 'manual__2024-05-23T14:06:40.025463+00:00', '--job-id', '633', '--raw', '--subdir', 'DAGS_FOLDER/get_main_games.py', '--cfg-path', '/tmp/tmpew732b32']
[2024-05-23T14:11:31.890+0000] {standard_task_runner.py:91} INFO - Job 633: Subtask load_data
[2024-05-23T14:11:31.917+0000] {task_command.py:426} INFO - Running <TaskInstance: games.load_data manual__2024-05-23T14:06:40.025463+00:00 [running]> on host 8be3070d766d
[2024-05-23T14:11:31.967+0000] {taskinstance.py:2644} INFO - Exporting env vars: AIRFLOW_CTX_DAG_OWNER='***' AIRFLOW_CTX_DAG_ID='games' AIRFLOW_CTX_TASK_ID='load_data' AIRFLOW_CTX_EXECUTION_DATE='2024-05-23T14:06:40.025463+00:00' AIRFLOW_CTX_TRY_NUMBER='1' AIRFLOW_CTX_DAG_RUN_ID='manual__2024-05-23T14:06:40.025463+00:00'
[2024-05-23T14:11:31.968+0000] {taskinstance.py:430} INFO - ::endgroup::
[2024-05-23T14:11:31.989+0000] {base.py:84} INFO - Using connection ID '***' for task execution.
[2024-05-23T14:11:31.996+0000] {base.py:84} INFO - Using connection ID '***' for task execution.
[2024-05-23T14:11:32.528+0000] {taskinstance.py:441} INFO - ::group::Post task execution logs
[2024-05-23T14:11:32.528+0000] {taskinstance.py:2890} ERROR - Task failed with exception
Traceback (most recent call last):
  File "/home/airflow/.local/lib/python3.12/site-packages/airflow/models/taskinstance.py", line 465, in _execute_task
    result = _execute_callable(context=context, **execute_callable_kwargs)
             ^^^^^^^^^^^^^^^^^^^^^^^^^^^^^^^^^^^^^^^^^^^^^^^^^^^^^^^^^^^^^
  File "/home/airflow/.local/lib/python3.12/site-packages/airflow/models/taskinstance.py", line 432, in _execute_callable
    return execute_callable(context=context, **execute_callable_kwargs)
           ^^^^^^^^^^^^^^^^^^^^^^^^^^^^^^^^^^^^^^^^^^^^^^^^^^^^^^^^^^^^
  File "/home/airflow/.local/lib/python3.12/site-packages/airflow/models/baseoperator.py", line 400, in wrapper
    return func(self, *args, **kwargs)
           ^^^^^^^^^^^^^^^^^^^^^^^^^^^
  File "/home/airflow/.local/lib/python3.12/site-packages/airflow/operators/python.py", line 235, in execute
    return_value = self.execute_callable()
                   ^^^^^^^^^^^^^^^^^^^^^^^
  File "/home/airflow/.local/lib/python3.12/site-packages/airflow/operators/python.py", line 252, in execute_callable
    return self.python_callable(*self.op_args, **self.op_kwargs)
           ^^^^^^^^^^^^^^^^^^^^^^^^^^^^^^^^^^^^^^^^^^^^^^^^^^^^^
  File "/opt/airflow/plugins/steps/get_matches.py", line 171, in load_data
    hook.insert_rows(
  File "/home/airflow/.local/lib/python3.12/site-packages/airflow/providers/common/sql/hooks/sql.py", line 573, in insert_rows
    cur.execute(sql, values)
psycopg2.errors.UndefinedColumn: column "team_1_accurate_through_ball" of relation "games" does not exist
LINE 1: ... team_1_big_chance_created, team_1_att_miss_left, team_1_acc...
                                                             ^

[2024-05-23T14:11:32.535+0000] {taskinstance.py:1205} INFO - Marking task as FAILED. dag_id=games, task_id=load_data, execution_date=20240523T140640, start_date=20240523T141131, end_date=20240523T141132
[2024-05-23T14:11:32.561+0000] {standard_task_runner.py:110} ERROR - Failed to execute job 633 for task load_data (column "team_1_accurate_through_ball" of relation "games" does not exist
LINE 1: ... team_1_big_chance_created, team_1_att_miss_left, team_1_acc...
                                                             ^
; 172)
[2024-05-23T14:11:32.583+0000] {local_task_job_runner.py:240} INFO - Task exited with return code 1
[2024-05-23T14:11:32.594+0000] {taskinstance.py:3482} INFO - 0 downstream tasks scheduled from follow-on schedule check
[2024-05-23T14:11:32.595+0000] {local_task_job_runner.py:222} INFO - ::endgroup::
