[2024-04-20T17:08:10.023+0000] {taskinstance.py:1159} INFO - Dependencies all met for dep_context=non-requeueable deps ti=<TaskInstance: season.load_step manual__2024-04-20T17:08:09.210302+00:00 [queued]>
[2024-04-20T17:08:10.028+0000] {taskinstance.py:1159} INFO - Dependencies all met for dep_context=requeueable deps ti=<TaskInstance: season.load_step manual__2024-04-20T17:08:09.210302+00:00 [queued]>
[2024-04-20T17:08:10.028+0000] {taskinstance.py:1361} INFO - Starting attempt 1 of 1
[2024-04-20T17:08:10.034+0000] {taskinstance.py:1382} INFO - Executing <Task(PythonOperator): load_step> on 2024-04-20 17:08:09.210302+00:00
[2024-04-20T17:08:10.039+0000] {standard_task_runner.py:57} INFO - Started process 68 to run task
[2024-04-20T17:08:10.041+0000] {standard_task_runner.py:84} INFO - Running: ['***', 'tasks', 'run', 'season', 'load_step', 'manual__2024-04-20T17:08:09.210302+00:00', '--job-id', '137', '--raw', '--subdir', 'DAGS_FOLDER/get_seasons.py', '--cfg-path', '/tmp/tmprx3qve01']
[2024-04-20T17:08:10.042+0000] {standard_task_runner.py:85} INFO - Job 137: Subtask load_step
[2024-04-20T17:08:10.069+0000] {task_command.py:416} INFO - Running <TaskInstance: season.load_step manual__2024-04-20T17:08:09.210302+00:00 [running]> on host 67d087abda7a
[2024-04-20T17:08:10.261+0000] {taskinstance.py:1662} INFO - Exporting env vars: AIRFLOW_CTX_DAG_OWNER='***' AIRFLOW_CTX_DAG_ID='season' AIRFLOW_CTX_TASK_ID='load_step' AIRFLOW_CTX_EXECUTION_DATE='2024-04-20T17:08:09.210302+00:00' AIRFLOW_CTX_TRY_NUMBER='1' AIRFLOW_CTX_DAG_RUN_ID='manual__2024-04-20T17:08:09.210302+00:00'
[2024-04-20T17:08:10.274+0000] {base.py:73} INFO - Using connection ID 'my_db' for task execution.
[2024-04-20T17:08:10.274+0000] {taskinstance.py:1937} ERROR - Task failed with exception
Traceback (most recent call last):
  File "/home/airflow/.local/lib/python3.10/site-packages/airflow/operators/python.py", line 192, in execute
    return_value = self.execute_callable()
  File "/home/airflow/.local/lib/python3.10/site-packages/airflow/operators/python.py", line 209, in execute_callable
    return self.python_callable(*self.op_args, **self.op_kwargs)
  File "/opt/airflow/plugins/steps/get_id_season.py", line 45, in load
    hook.insert_rows(
  File "/home/airflow/.local/lib/python3.10/site-packages/airflow/providers/common/sql/hooks/sql.py", line 510, in insert_rows
    with closing(self.get_conn()) as conn:
  File "/home/airflow/.local/lib/python3.10/site-packages/airflow/providers/postgres/hooks/postgres.py", line 158, in get_conn
    self.conn = psycopg2.connect(**conn_args)
  File "/home/airflow/.local/lib/python3.10/site-packages/psycopg2/__init__.py", line 122, in connect
    conn = _connect(dsn, connection_factory=connection_factory, **kwasync)
psycopg2.OperationalError: connection to server at "localhost" (::1), port 5432 failed: Connection refused
	Is the server running on that host and accepting TCP/IP connections?
connection to server at "localhost" (127.0.0.1), port 5432 failed: Connection refused
	Is the server running on that host and accepting TCP/IP connections?

[2024-04-20T17:08:10.279+0000] {taskinstance.py:1400} INFO - Marking task as FAILED. dag_id=season, task_id=load_step, execution_date=20240420T170809, start_date=20240420T170810, end_date=20240420T170810
[2024-04-20T17:08:10.285+0000] {standard_task_runner.py:104} ERROR - Failed to execute job 137 for task load_step (connection to server at "localhost" (::1), port 5432 failed: Connection refused
	Is the server running on that host and accepting TCP/IP connections?
connection to server at "localhost" (127.0.0.1), port 5432 failed: Connection refused
	Is the server running on that host and accepting TCP/IP connections?
; 68)
[2024-04-20T17:08:10.332+0000] {local_task_job_runner.py:228} INFO - Task exited with return code 1
[2024-04-20T17:08:10.343+0000] {taskinstance.py:2778} INFO - 0 downstream tasks scheduled from follow-on schedule check
