[2024-04-21T18:47:57.672+0000] {local_task_job_runner.py:120} INFO - ::group::Pre task execution logs
[2024-04-21T18:47:57.685+0000] {taskinstance.py:2073} INFO - Dependencies all met for dep_context=non-requeueable deps ti=<TaskInstance: get_seasons.load_data manual__2024-04-21T18:47:50.832338+00:00 [queued]>
[2024-04-21T18:47:57.689+0000] {taskinstance.py:2073} INFO - Dependencies all met for dep_context=requeueable deps ti=<TaskInstance: get_seasons.load_data manual__2024-04-21T18:47:50.832338+00:00 [queued]>
[2024-04-21T18:47:57.689+0000] {taskinstance.py:2303} INFO - Starting attempt 1 of 1
[2024-04-21T18:47:57.696+0000] {taskinstance.py:2327} INFO - Executing <Task(PythonOperator): load_data> on 2024-04-21 18:47:50.832338+00:00
[2024-04-21T18:47:57.703+0000] {warnings.py:110} WARNING - /home/***/.local/lib/python3.12/site-packages/***/task/task_runner/standard_task_runner.py:61: DeprecationWarning: This process (pid=78) is multi-threaded, use of fork() may lead to deadlocks in the child.
  pid = os.fork()

[2024-04-21T18:47:57.704+0000] {standard_task_runner.py:63} INFO - Started process 80 to run task
[2024-04-21T18:47:57.705+0000] {standard_task_runner.py:90} INFO - Running: ['***', 'tasks', 'run', 'get_seasons', 'load_data', 'manual__2024-04-21T18:47:50.832338+00:00', '--job-id', '105', '--raw', '--subdir', 'DAGS_FOLDER/get_seasons.py', '--cfg-path', '/tmp/tmp1b7fwvlm']
[2024-04-21T18:47:57.706+0000] {standard_task_runner.py:91} INFO - Job 105: Subtask load_data
[2024-04-21T18:47:57.736+0000] {task_command.py:426} INFO - Running <TaskInstance: get_seasons.load_data manual__2024-04-21T18:47:50.832338+00:00 [running]> on host 2929fdf4b0e1
[2024-04-21T18:47:57.794+0000] {taskinstance.py:2644} INFO - Exporting env vars: AIRFLOW_CTX_DAG_OWNER='***' AIRFLOW_CTX_DAG_ID='get_seasons' AIRFLOW_CTX_TASK_ID='load_data' AIRFLOW_CTX_EXECUTION_DATE='2024-04-21T18:47:50.832338+00:00' AIRFLOW_CTX_TRY_NUMBER='1' AIRFLOW_CTX_DAG_RUN_ID='manual__2024-04-21T18:47:50.832338+00:00'
[2024-04-21T18:47:57.795+0000] {taskinstance.py:430} INFO - ::endgroup::
[2024-04-21T18:47:57.807+0000] {base.py:84} INFO - Using connection ID '***' for task execution.
[2024-04-21T18:47:58.324+0000] {taskinstance.py:441} INFO - ::group::Post task execution logs
[2024-04-21T18:47:58.324+0000] {taskinstance.py:2890} ERROR - Task failed with exception
Traceback (most recent call last):
  File "/home/airflow/.local/lib/python3.12/site-packages/airflow/models/taskinstance.py", line 465, in _execute_task
    result = _execute_callable(context=context, **execute_callable_kwargs)
             ^^^^^^^^^^^^^^^^^^^^^^^^^^^^^^^^^^^^^^^^^^^^^^^^^^^^^^^^^^^^^
  File "/home/airflow/.local/lib/python3.12/site-packages/airflow/models/taskinstance.py", line 432, in _execute_callable
    return execute_callable(context=context, **execute_callable_kwargs)
           ^^^^^^^^^^^^^^^^^^^^^^^^^^^^^^^^^^^^^^^^^^^^^^^^^^^^^^^^^^^^
  File "/home/airflow/.local/lib/python3.12/site-packages/airflow/models/baseoperator.py", line 400, in wrapper
    return func(self, *args, **kwargs)
           ^^^^^^^^^^^^^^^^^^^^^^^^^^^
  File "/home/airflow/.local/lib/python3.12/site-packages/airflow/operators/python.py", line 235, in execute
    return_value = self.execute_callable()
                   ^^^^^^^^^^^^^^^^^^^^^^^
  File "/home/airflow/.local/lib/python3.12/site-packages/airflow/operators/python.py", line 252, in execute_callable
    return self.python_callable(*self.op_args, **self.op_kwargs)
           ^^^^^^^^^^^^^^^^^^^^^^^^^^^^^^^^^^^^^^^^^^^^^^^^^^^^^
  File "/opt/airflow/plugins/steps/get_id_season.py", line 59, in load_data
    hook.insert_rows(
  File "/home/airflow/.local/lib/python3.12/site-packages/airflow/providers/common/sql/hooks/sql.py", line 573, in insert_rows
    cur.execute(sql, values)
psycopg2.errors.UndefinedTable: relation "seasons" does not exist
LINE 1: INSERT INTO seasons (label, id) VALUES ('2023/24',578.0) ON ...
                    ^

[2024-04-21T18:47:58.331+0000] {taskinstance.py:1205} INFO - Marking task as FAILED. dag_id=get_seasons, task_id=load_data, execution_date=20240421T184750, start_date=20240421T184757, end_date=20240421T184758
[2024-04-21T18:47:58.350+0000] {standard_task_runner.py:110} ERROR - Failed to execute job 105 for task load_data (relation "seasons" does not exist
LINE 1: INSERT INTO seasons (label, id) VALUES ('2023/24',578.0) ON ...
                    ^
; 80)
[2024-04-21T18:47:58.398+0000] {local_task_job_runner.py:240} INFO - Task exited with return code 1
[2024-04-21T18:47:58.409+0000] {taskinstance.py:3482} INFO - 0 downstream tasks scheduled from follow-on schedule check
[2024-04-21T18:47:58.412+0000] {local_task_job_runner.py:222} INFO - ::endgroup::
