[2024-05-23T15:00:01.641+0000] {local_task_job_runner.py:120} INFO - ::group::Pre task execution logs
[2024-05-23T15:00:01.654+0000] {taskinstance.py:2073} INFO - Dependencies all met for dep_context=non-requeueable deps ti=<TaskInstance: games.load_data manual__2024-05-23T14:55:06.502478+00:00 [queued]>
[2024-05-23T15:00:01.658+0000] {taskinstance.py:2073} INFO - Dependencies all met for dep_context=requeueable deps ti=<TaskInstance: games.load_data manual__2024-05-23T14:55:06.502478+00:00 [queued]>
[2024-05-23T15:00:01.658+0000] {taskinstance.py:2303} INFO - Starting attempt 1 of 1
[2024-05-23T15:00:01.665+0000] {taskinstance.py:2327} INFO - Executing <Task(PythonOperator): load_data> on 2024-05-23 14:55:06.502478+00:00
[2024-05-23T15:00:01.672+0000] {warnings.py:110} WARNING - /home/***/.local/lib/python3.12/site-packages/***/task/task_runner/standard_task_runner.py:61: DeprecationWarning: This process (pid=135) is multi-threaded, use of fork() may lead to deadlocks in the child.
  pid = os.fork()

[2024-05-23T15:00:01.673+0000] {standard_task_runner.py:63} INFO - Started process 137 to run task
[2024-05-23T15:00:01.673+0000] {standard_task_runner.py:90} INFO - Running: ['***', 'tasks', 'run', 'games', 'load_data', 'manual__2024-05-23T14:55:06.502478+00:00', '--job-id', '645', '--raw', '--subdir', 'DAGS_FOLDER/get_main_games.py', '--cfg-path', '/tmp/tmpg78dtdt0']
[2024-05-23T15:00:01.674+0000] {standard_task_runner.py:91} INFO - Job 645: Subtask load_data
[2024-05-23T15:00:01.698+0000] {task_command.py:426} INFO - Running <TaskInstance: games.load_data manual__2024-05-23T14:55:06.502478+00:00 [running]> on host 0609ec5cc9c0
[2024-05-23T15:00:01.751+0000] {taskinstance.py:2644} INFO - Exporting env vars: AIRFLOW_CTX_DAG_OWNER='***' AIRFLOW_CTX_DAG_ID='games' AIRFLOW_CTX_TASK_ID='load_data' AIRFLOW_CTX_EXECUTION_DATE='2024-05-23T14:55:06.502478+00:00' AIRFLOW_CTX_TRY_NUMBER='1' AIRFLOW_CTX_DAG_RUN_ID='manual__2024-05-23T14:55:06.502478+00:00'
[2024-05-23T15:00:01.752+0000] {taskinstance.py:430} INFO - ::endgroup::
[2024-05-23T15:00:01.774+0000] {base.py:84} INFO - Using connection ID '***' for task execution.
[2024-05-23T15:00:01.781+0000] {base.py:84} INFO - Using connection ID '***' for task execution.
[2024-05-23T15:00:02.338+0000] {taskinstance.py:441} INFO - ::group::Post task execution logs
[2024-05-23T15:00:02.339+0000] {taskinstance.py:2890} ERROR - Task failed with exception
Traceback (most recent call last):
  File "/home/airflow/.local/lib/python3.12/site-packages/airflow/models/taskinstance.py", line 465, in _execute_task
    result = _execute_callable(context=context, **execute_callable_kwargs)
             ^^^^^^^^^^^^^^^^^^^^^^^^^^^^^^^^^^^^^^^^^^^^^^^^^^^^^^^^^^^^^
  File "/home/airflow/.local/lib/python3.12/site-packages/airflow/models/taskinstance.py", line 432, in _execute_callable
    return execute_callable(context=context, **execute_callable_kwargs)
           ^^^^^^^^^^^^^^^^^^^^^^^^^^^^^^^^^^^^^^^^^^^^^^^^^^^^^^^^^^^^
  File "/home/airflow/.local/lib/python3.12/site-packages/airflow/models/baseoperator.py", line 400, in wrapper
    return func(self, *args, **kwargs)
           ^^^^^^^^^^^^^^^^^^^^^^^^^^^
  File "/home/airflow/.local/lib/python3.12/site-packages/airflow/operators/python.py", line 235, in execute
    return_value = self.execute_callable()
                   ^^^^^^^^^^^^^^^^^^^^^^^
  File "/home/airflow/.local/lib/python3.12/site-packages/airflow/operators/python.py", line 252, in execute_callable
    return self.python_callable(*self.op_args, **self.op_kwargs)
           ^^^^^^^^^^^^^^^^^^^^^^^^^^^^^^^^^^^^^^^^^^^^^^^^^^^^^
  File "/opt/airflow/plugins/steps/get_matches.py", line 171, in load_data
    hook.insert_rows(
  File "/home/airflow/.local/lib/python3.12/site-packages/airflow/providers/common/sql/hooks/sql.py", line 573, in insert_rows
    cur.execute(sql, values)
psycopg2.errors.NumericValueOutOfRange: integer out of range

[2024-05-23T15:00:02.346+0000] {taskinstance.py:1205} INFO - Marking task as FAILED. dag_id=games, task_id=load_data, execution_date=20240523T145506, start_date=20240523T150001, end_date=20240523T150002
[2024-05-23T15:00:02.360+0000] {standard_task_runner.py:110} ERROR - Failed to execute job 645 for task load_data (integer out of range
; 137)
[2024-05-23T15:00:02.407+0000] {local_task_job_runner.py:240} INFO - Task exited with return code 1
[2024-05-23T15:00:02.418+0000] {taskinstance.py:3482} INFO - 0 downstream tasks scheduled from follow-on schedule check
[2024-05-23T15:00:02.419+0000] {local_task_job_runner.py:222} INFO - ::endgroup::
