[2024-04-14T18:31:14.554+0000] {taskinstance.py:1159} INFO - Dependencies all met for dep_context=non-requeueable deps ti=<TaskInstance: season.load_step scheduled__2023-01-01T00:00:00+00:00 [queued]>
[2024-04-14T18:31:14.559+0000] {taskinstance.py:1159} INFO - Dependencies all met for dep_context=requeueable deps ti=<TaskInstance: season.load_step scheduled__2023-01-01T00:00:00+00:00 [queued]>
[2024-04-14T18:31:14.559+0000] {taskinstance.py:1361} INFO - Starting attempt 1 of 1
[2024-04-14T18:31:14.567+0000] {taskinstance.py:1382} INFO - Executing <Task(PythonOperator): load_step> on 2023-01-01 00:00:00+00:00
[2024-04-14T18:31:14.575+0000] {standard_task_runner.py:57} INFO - Started process 67 to run task
[2024-04-14T18:31:14.577+0000] {standard_task_runner.py:84} INFO - Running: ['***', 'tasks', 'run', 'season', 'load_step', 'scheduled__2023-01-01T00:00:00+00:00', '--job-id', '8', '--raw', '--subdir', 'DAGS_FOLDER/get_seasons.py', '--cfg-path', '/tmp/tmphtzc3azq']
[2024-04-14T18:31:14.579+0000] {standard_task_runner.py:85} INFO - Job 8: Subtask load_step
[2024-04-14T18:31:14.606+0000] {task_command.py:416} INFO - Running <TaskInstance: season.load_step scheduled__2023-01-01T00:00:00+00:00 [running]> on host 23b0ecedd6dd
[2024-04-14T18:31:14.813+0000] {taskinstance.py:1662} INFO - Exporting env vars: AIRFLOW_CTX_DAG_OWNER='***' AIRFLOW_CTX_DAG_ID='season' AIRFLOW_CTX_TASK_ID='load_step' AIRFLOW_CTX_EXECUTION_DATE='2023-01-01T00:00:00+00:00' AIRFLOW_CTX_TRY_NUMBER='1' AIRFLOW_CTX_DAG_RUN_ID='scheduled__2023-01-01T00:00:00+00:00'
[2024-04-14T18:31:14.824+0000] {base.py:73} INFO - Using connection ID 'my_db' for task execution.
[2024-04-14T18:31:14.825+0000] {taskinstance.py:1937} ERROR - Task failed with exception
Traceback (most recent call last):
  File "/home/airflow/.local/lib/python3.10/site-packages/airflow/operators/python.py", line 192, in execute
    return_value = self.execute_callable()
  File "/home/airflow/.local/lib/python3.10/site-packages/airflow/operators/python.py", line 209, in execute_callable
    return self.python_callable(*self.op_args, **self.op_kwargs)
  File "/opt/airflow/plugins/steps/get_id_season.py", line 45, in load
    hook.insert_rows(
  File "/home/airflow/.local/lib/python3.10/site-packages/airflow/providers/common/sql/hooks/sql.py", line 510, in insert_rows
    with closing(self.get_conn()) as conn:
  File "/home/airflow/.local/lib/python3.10/site-packages/airflow/providers/postgres/hooks/postgres.py", line 158, in get_conn
    self.conn = psycopg2.connect(**conn_args)
  File "/home/airflow/.local/lib/python3.10/site-packages/psycopg2/__init__.py", line 122, in connect
    conn = _connect(dsn, connection_factory=connection_factory, **kwasync)
psycopg2.OperationalError: connection to server at "127.0.0.1", port 5432 failed: Connection refused
	Is the server running on that host and accepting TCP/IP connections?

[2024-04-14T18:31:14.830+0000] {taskinstance.py:1400} INFO - Marking task as FAILED. dag_id=season, task_id=load_step, execution_date=20230101T000000, start_date=20240414T183114, end_date=20240414T183114
[2024-04-14T18:31:14.835+0000] {standard_task_runner.py:104} ERROR - Failed to execute job 8 for task load_step (connection to server at "127.0.0.1", port 5432 failed: Connection refused
	Is the server running on that host and accepting TCP/IP connections?
; 67)
[2024-04-14T18:31:14.869+0000] {local_task_job_runner.py:228} INFO - Task exited with return code 1
[2024-04-14T18:31:14.887+0000] {taskinstance.py:2778} INFO - 0 downstream tasks scheduled from follow-on schedule check
[2024-04-20T18:51:02.987+0000] {local_task_job_runner.py:120} INFO - ::group::Pre task execution logs
[2024-04-20T18:51:03.003+0000] {taskinstance.py:2073} INFO - Dependencies all met for dep_context=non-requeueable deps ti=<TaskInstance: season.load_step scheduled__2023-01-01T00:00:00+00:00 [queued]>
[2024-04-20T18:51:03.007+0000] {taskinstance.py:2073} INFO - Dependencies all met for dep_context=requeueable deps ti=<TaskInstance: season.load_step scheduled__2023-01-01T00:00:00+00:00 [queued]>
[2024-04-20T18:51:03.007+0000] {taskinstance.py:2303} INFO - Starting attempt 1 of 1
[2024-04-20T18:51:03.015+0000] {taskinstance.py:2327} INFO - Executing <Task(PythonOperator): load_step> on 2023-01-01 00:00:00+00:00
[2024-04-20T18:51:03.023+0000] {warnings.py:110} WARNING - /home/***/.local/lib/python3.12/site-packages/***/task/task_runner/standard_task_runner.py:61: DeprecationWarning: This process (pid=57) is multi-threaded, use of fork() may lead to deadlocks in the child.
  pid = os.fork()

[2024-04-20T18:51:03.024+0000] {standard_task_runner.py:63} INFO - Started process 66 to run task
[2024-04-20T18:51:03.023+0000] {standard_task_runner.py:90} INFO - Running: ['***', 'tasks', 'run', 'season', 'load_step', 'scheduled__2023-01-01T00:00:00+00:00', '--job-id', '5', '--raw', '--subdir', 'DAGS_FOLDER/get_seasons.py', '--cfg-path', '/tmp/tmp1uo43afr']
[2024-04-20T18:51:03.025+0000] {standard_task_runner.py:91} INFO - Job 5: Subtask load_step
[2024-04-20T18:51:03.051+0000] {task_command.py:426} INFO - Running <TaskInstance: season.load_step scheduled__2023-01-01T00:00:00+00:00 [running]> on host 4cf9e140f22c
[2024-04-20T18:51:03.111+0000] {taskinstance.py:2644} INFO - Exporting env vars: AIRFLOW_CTX_DAG_OWNER='***' AIRFLOW_CTX_DAG_ID='season' AIRFLOW_CTX_TASK_ID='load_step' AIRFLOW_CTX_EXECUTION_DATE='2023-01-01T00:00:00+00:00' AIRFLOW_CTX_TRY_NUMBER='1' AIRFLOW_CTX_DAG_RUN_ID='scheduled__2023-01-01T00:00:00+00:00'
[2024-04-20T18:51:03.111+0000] {taskinstance.py:430} INFO - ::endgroup::
[2024-04-20T18:51:03.125+0000] {base.py:84} INFO - Using connection ID '***' for task execution.
[2024-04-20T18:51:03.126+0000] {taskinstance.py:441} INFO - ::group::Post task execution logs
[2024-04-20T18:51:03.126+0000] {taskinstance.py:2890} ERROR - Task failed with exception
Traceback (most recent call last):
  File "/home/airflow/.local/lib/python3.12/site-packages/airflow/models/taskinstance.py", line 465, in _execute_task
    result = _execute_callable(context=context, **execute_callable_kwargs)
             ^^^^^^^^^^^^^^^^^^^^^^^^^^^^^^^^^^^^^^^^^^^^^^^^^^^^^^^^^^^^^
  File "/home/airflow/.local/lib/python3.12/site-packages/airflow/models/taskinstance.py", line 432, in _execute_callable
    return execute_callable(context=context, **execute_callable_kwargs)
           ^^^^^^^^^^^^^^^^^^^^^^^^^^^^^^^^^^^^^^^^^^^^^^^^^^^^^^^^^^^^
  File "/home/airflow/.local/lib/python3.12/site-packages/airflow/models/baseoperator.py", line 400, in wrapper
    return func(self, *args, **kwargs)
           ^^^^^^^^^^^^^^^^^^^^^^^^^^^
  File "/home/airflow/.local/lib/python3.12/site-packages/airflow/operators/python.py", line 235, in execute
    return_value = self.execute_callable()
                   ^^^^^^^^^^^^^^^^^^^^^^^
  File "/home/airflow/.local/lib/python3.12/site-packages/airflow/operators/python.py", line 252, in execute_callable
    return self.python_callable(*self.op_args, **self.op_kwargs)
           ^^^^^^^^^^^^^^^^^^^^^^^^^^^^^^^^^^^^^^^^^^^^^^^^^^^^^
  File "/opt/airflow/plugins/steps/get_id_season.py", line 45, in load
    hook.insert_rows(
  File "/home/airflow/.local/lib/python3.12/site-packages/airflow/providers/common/sql/hooks/sql.py", line 544, in insert_rows
    with closing(self.get_conn()) as conn:
                 ^^^^^^^^^^^^^^^
  File "/home/airflow/.local/lib/python3.12/site-packages/airflow/providers/postgres/hooks/postgres.py", line 161, in get_conn
    self.conn = psycopg2.connect(**conn_args)
                ^^^^^^^^^^^^^^^^^^^^^^^^^^^^^
  File "/home/airflow/.local/lib/python3.12/site-packages/psycopg2/__init__.py", line 122, in connect
    conn = _connect(dsn, connection_factory=connection_factory, **kwasync)
           ^^^^^^^^^^^^^^^^^^^^^^^^^^^^^^^^^^^^^^^^^^^^^^^^^^^^^^^^^^^^^^^
psycopg2.OperationalError: connection to server at "127.0.0.1", port 5432 failed: Connection refused
	Is the server running on that host and accepting TCP/IP connections?

[2024-04-20T18:51:03.132+0000] {taskinstance.py:1205} INFO - Marking task as FAILED. dag_id=season, task_id=load_step, execution_date=20230101T000000, start_date=20240420T185103, end_date=20240420T185103
[2024-04-20T18:51:03.139+0000] {standard_task_runner.py:110} ERROR - Failed to execute job 5 for task load_step (connection to server at "127.0.0.1", port 5432 failed: Connection refused
	Is the server running on that host and accepting TCP/IP connections?
; 66)
[2024-04-20T18:51:03.156+0000] {local_task_job_runner.py:240} INFO - Task exited with return code 1
[2024-04-20T18:51:03.171+0000] {taskinstance.py:3482} INFO - 0 downstream tasks scheduled from follow-on schedule check
[2024-04-20T18:51:03.172+0000] {local_task_job_runner.py:222} INFO - ::endgroup::
